01/11/21 (08:27:48) | ERROR: <urlopen error _ssl.c:980: The handshake operation timed out>
Traceback (most recent call last):
  File "/usr/local/Cellar/python@3.10/3.10.0_2/Frameworks/Python.framework/Versions/3.10/lib/python3.10/urllib/request.py", line 1348, in do_open
    h.request(req.get_method(), req.selector, req.data, headers,
  File "/usr/local/Cellar/python@3.10/3.10.0_2/Frameworks/Python.framework/Versions/3.10/lib/python3.10/http/client.py", line 1276, in request
    self._send_request(method, url, body, headers, encode_chunked)
  File "/usr/local/Cellar/python@3.10/3.10.0_2/Frameworks/Python.framework/Versions/3.10/lib/python3.10/http/client.py", line 1322, in _send_request
    self.endheaders(body, encode_chunked=encode_chunked)
  File "/usr/local/Cellar/python@3.10/3.10.0_2/Frameworks/Python.framework/Versions/3.10/lib/python3.10/http/client.py", line 1271, in endheaders
    self._send_output(message_body, encode_chunked=encode_chunked)
  File "/usr/local/Cellar/python@3.10/3.10.0_2/Frameworks/Python.framework/Versions/3.10/lib/python3.10/http/client.py", line 1031, in _send_output
    self.send(msg)
  File "/usr/local/Cellar/python@3.10/3.10.0_2/Frameworks/Python.framework/Versions/3.10/lib/python3.10/http/client.py", line 969, in send
    self.connect()
  File "/usr/local/Cellar/python@3.10/3.10.0_2/Frameworks/Python.framework/Versions/3.10/lib/python3.10/http/client.py", line 1448, in connect
    self.sock = self._context.wrap_socket(self.sock,
  File "/usr/local/Cellar/python@3.10/3.10.0_2/Frameworks/Python.framework/Versions/3.10/lib/python3.10/ssl.py", line 512, in wrap_socket
    return self.sslsocket_class._create(
  File "/usr/local/Cellar/python@3.10/3.10.0_2/Frameworks/Python.framework/Versions/3.10/lib/python3.10/ssl.py", line 1070, in _create
    self.do_handshake()
  File "/usr/local/Cellar/python@3.10/3.10.0_2/Frameworks/Python.framework/Versions/3.10/lib/python3.10/ssl.py", line 1341, in do_handshake
    self._sslobj.do_handshake()
TimeoutError: _ssl.c:980: The handshake operation timed out

During handling of the above exception, another exception occurred:

Traceback (most recent call last):
  File "/usr/local/bin/bpytop", line 5009, in _checker
    with urllib.request.urlopen("https://github.com/aristocratos/bpytop/raw/master/bpytop.py", timeout=5) as source: # type: ignore
  File "/usr/local/Cellar/python@3.10/3.10.0_2/Frameworks/Python.framework/Versions/3.10/lib/python3.10/urllib/request.py", line 216, in urlopen
    return opener.open(url, data, timeout)
  File "/usr/local/Cellar/python@3.10/3.10.0_2/Frameworks/Python.framework/Versions/3.10/lib/python3.10/urllib/request.py", line 519, in open
    response = self._open(req, data)
  File "/usr/local/Cellar/python@3.10/3.10.0_2/Frameworks/Python.framework/Versions/3.10/lib/python3.10/urllib/request.py", line 536, in _open
    result = self._call_chain(self.handle_open, protocol, protocol +
  File "/usr/local/Cellar/python@3.10/3.10.0_2/Frameworks/Python.framework/Versions/3.10/lib/python3.10/urllib/request.py", line 496, in _call_chain
    result = func(*args)
  File "/usr/local/Cellar/python@3.10/3.10.0_2/Frameworks/Python.framework/Versions/3.10/lib/python3.10/urllib/request.py", line 1391, in https_open
    return self.do_open(http.client.HTTPSConnection, req,
  File "/usr/local/Cellar/python@3.10/3.10.0_2/Frameworks/Python.framework/Versions/3.10/lib/python3.10/urllib/request.py", line 1351, in do_open
    raise URLError(err)
urllib.error.URLError: <urlopen error _ssl.c:980: The handshake operation timed out>
01/11/21 (08:36:20) | ERROR: <urlopen error _ssl.c:980: The handshake operation timed out>
Traceback (most recent call last):
  File "/usr/local/Cellar/python@3.10/3.10.0_2/Frameworks/Python.framework/Versions/3.10/lib/python3.10/urllib/request.py", line 1348, in do_open
    h.request(req.get_method(), req.selector, req.data, headers,
  File "/usr/local/Cellar/python@3.10/3.10.0_2/Frameworks/Python.framework/Versions/3.10/lib/python3.10/http/client.py", line 1276, in request
    self._send_request(method, url, body, headers, encode_chunked)
  File "/usr/local/Cellar/python@3.10/3.10.0_2/Frameworks/Python.framework/Versions/3.10/lib/python3.10/http/client.py", line 1322, in _send_request
    self.endheaders(body, encode_chunked=encode_chunked)
  File "/usr/local/Cellar/python@3.10/3.10.0_2/Frameworks/Python.framework/Versions/3.10/lib/python3.10/http/client.py", line 1271, in endheaders
    self._send_output(message_body, encode_chunked=encode_chunked)
  File "/usr/local/Cellar/python@3.10/3.10.0_2/Frameworks/Python.framework/Versions/3.10/lib/python3.10/http/client.py", line 1031, in _send_output
    self.send(msg)
  File "/usr/local/Cellar/python@3.10/3.10.0_2/Frameworks/Python.framework/Versions/3.10/lib/python3.10/http/client.py", line 969, in send
    self.connect()
  File "/usr/local/Cellar/python@3.10/3.10.0_2/Frameworks/Python.framework/Versions/3.10/lib/python3.10/http/client.py", line 1448, in connect
    self.sock = self._context.wrap_socket(self.sock,
  File "/usr/local/Cellar/python@3.10/3.10.0_2/Frameworks/Python.framework/Versions/3.10/lib/python3.10/ssl.py", line 512, in wrap_socket
    return self.sslsocket_class._create(
  File "/usr/local/Cellar/python@3.10/3.10.0_2/Frameworks/Python.framework/Versions/3.10/lib/python3.10/ssl.py", line 1070, in _create
    self.do_handshake()
  File "/usr/local/Cellar/python@3.10/3.10.0_2/Frameworks/Python.framework/Versions/3.10/lib/python3.10/ssl.py", line 1341, in do_handshake
    self._sslobj.do_handshake()
TimeoutError: _ssl.c:980: The handshake operation timed out

During handling of the above exception, another exception occurred:

Traceback (most recent call last):
  File "/usr/local/bin/bpytop", line 5009, in _checker
    with urllib.request.urlopen("https://github.com/aristocratos/bpytop/raw/master/bpytop.py", timeout=5) as source: # type: ignore
  File "/usr/local/Cellar/python@3.10/3.10.0_2/Frameworks/Python.framework/Versions/3.10/lib/python3.10/urllib/request.py", line 216, in urlopen
    return opener.open(url, data, timeout)
  File "/usr/local/Cellar/python@3.10/3.10.0_2/Frameworks/Python.framework/Versions/3.10/lib/python3.10/urllib/request.py", line 525, in open
    response = meth(req, response)
  File "/usr/local/Cellar/python@3.10/3.10.0_2/Frameworks/Python.framework/Versions/3.10/lib/python3.10/urllib/request.py", line 634, in http_response
    response = self.parent.error(
  File "/usr/local/Cellar/python@3.10/3.10.0_2/Frameworks/Python.framework/Versions/3.10/lib/python3.10/urllib/request.py", line 557, in error
    result = self._call_chain(*args)
  File "/usr/local/Cellar/python@3.10/3.10.0_2/Frameworks/Python.framework/Versions/3.10/lib/python3.10/urllib/request.py", line 496, in _call_chain
    result = func(*args)
  File "/usr/local/Cellar/python@3.10/3.10.0_2/Frameworks/Python.framework/Versions/3.10/lib/python3.10/urllib/request.py", line 749, in http_error_302
    return self.parent.open(new, timeout=req.timeout)
  File "/usr/local/Cellar/python@3.10/3.10.0_2/Frameworks/Python.framework/Versions/3.10/lib/python3.10/urllib/request.py", line 519, in open
    response = self._open(req, data)
  File "/usr/local/Cellar/python@3.10/3.10.0_2/Frameworks/Python.framework/Versions/3.10/lib/python3.10/urllib/request.py", line 536, in _open
    result = self._call_chain(self.handle_open, protocol, protocol +
  File "/usr/local/Cellar/python@3.10/3.10.0_2/Frameworks/Python.framework/Versions/3.10/lib/python3.10/urllib/request.py", line 496, in _call_chain
    result = func(*args)
  File "/usr/local/Cellar/python@3.10/3.10.0_2/Frameworks/Python.framework/Versions/3.10/lib/python3.10/urllib/request.py", line 1391, in https_open
    return self.do_open(http.client.HTTPSConnection, req,
  File "/usr/local/Cellar/python@3.10/3.10.0_2/Frameworks/Python.framework/Versions/3.10/lib/python3.10/urllib/request.py", line 1351, in do_open
    raise URLError(err)
urllib.error.URLError: <urlopen error _ssl.c:980: The handshake operation timed out>
